Workbook

Sheet Business
A1: Country | B1: Plant | C1: Type | D1: Products | E1: Environmental Performance
E2: Raw Material | F2: Production | G2: Energy | I2: Air | M2: Water | O2: Waste
G3: Thermal | H3: Electricity | I3: Dust | J3: SOx | K3: NOx | L3: GHG | M3: Withdrawal | N3: Recycled
A4: Indonesia | B4: SJW | C4: Production | D4: Cement | E4: Yes | F4: Yes | G4: Yes | H4: Yes | I4: Yes | J4: Yes | K4: Yes | L4: Yes | M4: Yes | N4: Yes | O4: Yes
A5: Indonesia | B5: SLCI | C5: Production | D5: Concrete Lightweight | E5: Yes | F5: Yes | G5: Yes | H5: Yes | I5: Yes | J5: Yes | K5: Yes | L5: Yes | M5: Yes | N5: Yes | O5: Yes
A6: Indonesia | B6: SICP | C6: Production | D6: Fibercement Roof | E6: Yes | F6: Yes | G6: Yes | H6: Yes | I6: Yes | J6: Yes | K6: Yes | L6: Yes | M6: Yes | N6: Yes | O6: Yes
A7: Indonesia | B7: SIGI | C7: Production | D7: Gypsum | E7: Yes | F7: Yes | G7: Yes | H7: Yes | I7: Yes | J7: Yes | K7: Yes | L7: Yes | M7: Yes | N7: Yes | O7: Yes
A8: Indonesia | B8: SRMI | C8: Production | D8: Concrete Ready Mix | E8: Yes | F8: Yes | G8: Yes | H8: Yes | I8: No | J8: No | K8: No | L8: Yes | M8: Yes | N8: Yes | O8: Yes
A9: Indonesia | B9: SPPI | C9: Production | D9: Concrete Precast | E9: Yes | F9: Yes | G9: Yes | H9: Yes | I9: No | J9: No | K9: No | L9: Yes | M9: Yes | N9: Yes | O9: Yes
A10: Indonesia | B10: KIA | C10: Production | D10: Ceramics | E10: Yes | F10: Yes | G10: Yes | H10: Yes | I10: Yes | J10: Yes | K10: Yes | L10: Yes | M10: Yes | N10: Yes | O10: Yes
A11: Indonesia | B11: SSK | C11: Production | D11: Ceramics | E11: Yes | F11: Yes | G11: Yes | H11: Yes | I11: Yes | J11: Yes | K11: Yes | L11: Yes | M11: Yes | N11: Yes | O11: Yes
A12: Indonesia | B12: KOKOH | C12: Logistic | D12: - | E12: - | F12: - | G12: - | H12: - | I12: - | J12: - | K12: - | L12: - | M12: - | N12: - | O12: -
A13: Indonesia | B13: Tambang Semen Sukabumi | C13: Quarry (SJW) | D13: - | E13: - | F13: - | G13: - | H13: - | I13: - | J13: - | K13: - | L13: - | M13: - | N13: - | O13: -
A14: Indonesia | B14: Semen Lebak | C14: Quarry (SJW) | D14: - | E14: - | F14: - | G14: - | H14: - | I14: - | J14: - | K14: - | L14: - | M14: - | N14: - | O14: -
A15: Indonesia | B15: Pion Quarry Nusantara | C15: Quarry (SRMI) | D15: - | E15: - | F15: - | G15: - | H15: - | I15: - | J15: - | K15: - | L15: - | M15: - | N15: - | O15: -
... A36: Philippines | B36: SMP | C36: Office | D36: - | E36: - | F36: - | G36: - | H36: - | I36: - | J36: - | K36: - | L36: - | M36: - | N36: - | O36: -

Sheet Scope
A2: Raw Materials
A3: Product Group | B3: Limestone | C3: Clay | D3: Sand | E3: Gypsum | F3: Laterite | G3: Cement | H3: Feldspar | I3: Aggregate | J3: Pottery Stone | K3: Frit | L3: Recycled Mat | M3: Others | N3: Shale | O3: Pyrophillyte | P3: Limestone Powder
A4: Cement | B4: Yes | C4: Yes | D4: Yes | E4: Yes | F4: Yes | G4: No | H4: No | I4: No | J4: No | K4: No | L4: -Synthesis Gypsum -Slag -Fly Ash (PHA) | M4: Yes | N4: Yes | O4: Yes | P4: Yes
A5: Concrete Ready Mix | B5: Yes | C5: No | D5: Yes | E5: No | F5: No | G5: Yes | H5: No | I5: Yes | J5: No | K5: No | L5: -Fly Ash (PHA) -Recycle Aggregate | M5: Yes | N5: No | O5: No | P5: No
A6: Concrete Precast | B6: Yes | C6: No | D6: Yes | E6: No | F6: No | G6: Yes | H6: No | I6: Yes | J6: No | K6: No | L6: Yes | M6: Yes | N6: No | O6: No | P6: No
A7: Concrete Roof | B7: Yes | C7: No | D7: Yes | E7: No | F7: No | G7: Yes | H7: No | I7: No | J7: No | K7: No | L7: No | M7: Yes | N7: No | O7: No | P7: No
A8: Concrete Lightweight | B8: Yes | C8: No | D8: Yes | E8: Yes | F8: No | G8: Yes | H8: No | I8: No | J8: No | K8: No | L8: No | M8: Yes | N8: No | O8: No | P8: No
A9: Fibercement Roof | B9: Yes | C9: No | D9: No | E9: No | F9: No | G9: Yes | H9: No | I9: No | J9: No | K9: No | L9: No | M9: Yes | N9: No | O9: No | P9: No
A10: Ceramics | B10: Yes | C10: Yes | D10: No | E10: Yes | F10: No | G10: No | H10: Yes | I10: No | J10: No | K10: Yes | L10: Yes | M10: Yes | N10: No | O10: No | P10: No
A11: Gypsum | B11: No | C11: No | D11: No | E11: Yes | F11: No | G11: No | H11: No | I11: No | J11: No | K11: No | L11: No | M11: Yes | N11: No | O11: No | P11: No
B13: Hazardous Waste | G13: Non Hazardous Waste
A14: Product Group | B14: Contaminated Cloth | C14: Used oil | D14: Package contaminated (Used paint can) | E14: Electronic equipment (light bulb/ battery) | F14: Insulation | G14: Process Waste | H14: Sludge | I14: Paper packaging | J14: Plastic packaging, (Wrap, Bigbag) | K14: Wooden Packaging (Pallet) | L14: Matelic Packaging | M14: Rubber | N14: Refractory
A15: Cement | B15: Yes | C15: Yes | D15: Yes | E15: Yes | F15: Yes | G15: Testing Concrete | H15: From wastewater treatment | I15: Yes | J15: Yes | K15: Yes | L15: Yes | M15: Yes | N15: Yes
A16: Concrete Ready Mix | B16: Yes | C16: Yes | D16: No | E16: No | F16: No | G16: Slump | H16: No | I16: No | J16: No | K16: No | L16: No | M16: No | N16: No
A17: Concrete Precast | B17: Yes | C17: Yes | D17: No | E17: No | F17: No | G17: Reject | H17: No | I17: No | J17: No | K17: No | L17: No | M17: No | N17: No
A18: Concrete Roof | B18: Yes | C18: Yes | D18: Yes | E18: Yes | F18: No | G18: Reject | H18: Yes | I18: Yes | J18: Yes | K18: Yes | L18: Yes | M18: No | N18: No
A19: Concrete Lightweight | B19: Yes | C19: Yes | D19: Yes | E19: Yes | F19: No | G19: Reject | H19: No | I19: Yes | J19: Yes | K19: Yes | L19: Yes | M19: Yes | N19: No
A20: Fibercement Roof | B20: Yes | C20: Yes | D20: Yes | E20: Yes | F20: No | G20: Reject | H20: Yes | I20: Yes | J20: Yes | K20: Yes | L20: Yes | M20: No | N20: No
A21: Ceramics | B21: Yes | C21: Yes | D21: Yes | E21: Yes | F21: Yes | G21: Reject | H21: Yes | I21: Yes | J21: Yes | K21: Yes | L21: Yes | M21: Yes | N21: Yes
A22: Gypsum | B22: Yes | C22: Yes | D22: Yes | E22: Yes | F22: No | G22: Reject | H22: Yes | I22: Yes | J22: Yes | K22: Yes | L22: Yes | M22: No | N22: No

Sheet Production, Raw Mat
A2: Production (DV Tile + YB Powder) | B2: unit | C2: Jan | D2: Feb | E2: Mar | F2: Apr | G2: May | H2: Jun | I2: Jul | J2: Aug | K2: Sep | L2: Oct | M2: Nov | N2: Dec | O2: YTD | P2: Q1 | Q2: Q2 | R2: Q3 | S2: Q4
A3: Production (DV Tile) (Sản phẩm ĐV) | B3: ton | C3: =9609931/1000 -> 9609.931 | D3: =6310080.93333333/1000 -> 6310.0809 | E3: =17732973.4666667/1000 -> 17732.973 | F3: =15795455.3666667/1000 -> 15795.455 | G3: =16091799.7666667/1000 -> 16091.8 | H3: =16408015.8333333/1000 -> 16408.016 | I3: =18454323.8047619/1000 -> 18454.324 | J3: =16179630.247619/1000 -> 16179.63 | K3: =12136760.3666667/1000 -> 12136.76 | L3: =12464841.21625/1000 -> 12464.841 | M3: =12324145.55/1000 -> 12324.146 | N3: =15580268.8233333/1000 -> 15580.269 | O3: =SUM(C3:N3) -> 169088.23 | P3: =SUM(C3:E3) -> 33652.985 | Q3: =SUM(F3:H3) -> 48295.271 | R3: =SUM(I3:K3) -> 46770.714 | S3: =SUM(L3:N3) -> 40369.256
A4: Production (YB Powder) (bột bán cho Yên Bình) | B4: ton | C4: 0 | D4: 0 | E4: 0 | F4: 0 | G4: 0 | N4: =423667.4/1000 -> 423.6674 | O4: =SUM(C4:N4) -> 423.6674 | P4: =SUM(C4:E4) -> 0 | Q4: =SUM(F4:H4) -> 0 | R4: =SUM(I4:K4) -> 0 | S4: =SUM(L4:N4) -> 423.6674
A5: Total Production (DV + YB) | B5: ton | C5: =SUM(C3:C4) -> 9609.931 | D5: =SUM(D3:D4) -> 6310.0809 | E5: =SUM(E3:E4) -> 17732.973 | F5: =SUM(F3:F4) -> 15795.455 | G5: =SUM(G3:G4) -> 16091.8 | H5: =SUM(H3:H4) -> 16408.016 | I5: =SUM(I3:I4) -> 18454.324 | J5: =SUM(J3:J4) -> 16179.63 | ... S5: =SUM(S3:S4) -> 40792.923
A7: Raw Material | B7: unit | C7: Jan | D7: Feb | E7: Mar | F7: Apr | G7: May | H7: Jun | I7: Jul | J7: Aug | K7: Sep | L7: Oct | M7: Nov | N7: Dec | O7: YTD | P7: Q1 | Q7: Q2 | R7: Q3 | S7: Q4
A8: Limestone/ Đá vôi (canxit) | B8: ton | C8: =1185210/1000 -> 1185.21 | D8: =903630/1000 -> 903.63 | E8: =2451735/1000 -> 2451.735 | F8: =2133495/1000 -> 2133.495 | G8: =2066220/1000 -> 2066.22 | H8: =2160795/1000 -> 2160.795 | I8: =2501265/1000 -> 2501.265 | J8: =2094690/1000 -> 2094.69 | K8: =1523340/1000 -> 1523.34 | L8: =1624155/1000 -> 1624.155 | M8: =1624350/1000 -> 1624.35 | N8: =1872750/1000 -> 1872.75 | O8: =SUM(C8:N8) -> 22141.635 | P8: =SUM(C8:E8) -> 4540.575 | Q8: =SUM(F8:H8) -> 6360.51 | R8: =SUM(I8:K8) -> 6119.295 | S8: =SUM(L8:N8) -> 5121.255
A9: Clay/ Đất sét | B9: ton | C9: =6280950/1000 -> 6280.95 | D9: =4812600/1000 -> 4812.6 | E9: =13112580/1000 -> 13112.58 | F9: =11433240/1000 -> 11433.24 | G9: =11029452/1000 -> 11029.452 | H9: =11323650/1000 -> 11323.65 | I9: =13526175/1000 -> 13526.175 | J9: =12506465/1000 -> 12506.465 | K9: =8783970/1000 -> 8783.97 | L9: =9729720/1000 -> 9729.72 | M9: =9687405/1000 -> 9687.405 | N9: =11518615/1000 -> 11518.615 | O9: =SUM(C9:N9) -> 123744.82 | P9: =SUM(C9:E9) -> 24206.13 | Q9: =SUM(F9:H9) -> 33786.342 | R9: =SUM(I9:K9) -> 34816.61 | S9: =SUM(L9:N9) -> 30935.74
A10: Sand/ Cát | B10: ton | O10: =SUM(C10:N10) -> 0 | P10: =SUM(C10:E10) -> 0 | Q10: =SUM(F10:H10) -> 0 | R10: =SUM(I10:K10) -> 0 | S10: =SUM(L10:N10) -> 0
A11: Gypsum/ Thạch cao | B11: ton | O11: =SUM(C11:N11) -> 0 | P11: =SUM(C11:E11) -> 0 | Q11: =SUM(F11:H11) -> 0 | R11: =SUM(I11:K11) -> 0 | S11: =SUM(L11:N11) -> 0
A12: Laterite/ Đá ong | B12: ton | O12: =SUM(C12:N12) -> 0 | P12: =SUM(C12:E12) -> 0 | Q12: =SUM(F12:H12) -> 0 | R12: =SUM(I12:K12) -> 0 | S12: =SUM(L12:N12) -> 0
A13: Cement/ Xi măng | B13: ton | O13: =SUM(C13:N13) -> 0 | P13: =SUM(C13:E13) -> 0 | Q13: =SUM(F13:H13) -> 0 | R13: =SUM(I13:K13) -> 0 | S13: =SUM(L13:N13) -> 0
A14: Feldspar | B14: ton | C14: =696150/1000 -> 696.15 | D14: =772200/1000 -> 772.2 | E14: =1762800/1000 -> 1762.8 | F14: =1414140/1000 -> 1414.14 | G14: =1600308/1000 -> 1600.308 | H14: =1814670/1000 -> 1814.67 | I14: =2458170/1000 -> 2458.17 | J14: =963300/1000 -> 963.3 | K14: =958620/1000 -> 958.62 | L14: =877500/1000 -> 877.5 | M14: =627900/1000 -> 627.9 | N14: =1141700/1000 -> 1141.7 | O14: =SUM(C14:N14) -> 15087.458 | P14: =SUM(C14:E14) -> 3231.15 | Q14: =SUM(F14:H14) -> 4829.118 | R14: =SUM(I14:K14) -> 4380.09 | S14: =SUM(L14:N14) -> 2647.1
A15: Aggregate/ Chất kết tụ | B15: ton | O15: =SUM(C15:N15) -> 0 | P15: =SUM(C15:E15) -> 0 | Q15: =SUM(F15:H15) -> 0 | R15: =SUM(I15:K15) -> 0 | S15: =SUM(L15:N15) -> 0
A16: Pottery Stone | B16: ton | O16: =SUM(C16:N16) -> 0 | P16: =SUM(C16:E16) -> 0 | Q16: =SUM(F16:H16) -> 0 | R16: =SUM(I16:K16) -> 0 | S16: =SUM(L16:N16) -> 0
A17: Glazing (Men ướt nhập VP quy khô) | B17: ton | C17: =611660/1000 -> 611.66 | D17: =593122/1000 -> 593.122 | E17: =1366899/1000 -> 1366.899 | F17: =1232648/1000 -> 1232.648 | G17: =1224313/1000 -> 1224.313 | H17: =1274894/1000 -> 1274.894 | I17: =1532653/1000 -> 1532.653 | J17: =1223418/1000 -> 1223.418 | K17: =908336/1000 -> 908.336 | L17: =1025460/1000 -> 1025.46 | M17: =906515/1000 -> 906.515 | N17: =1268747/1000 -> 1268.747 | O17: =SUM(C17:N17) -> 13168.665 | P17: =SUM(C17:E17) -> 2571.681 | Q17: =SUM(F17:H17) -> 3731.855 | R17: =SUM(I17:K17) -> 3664.407 | S17: =SUM(L17:N17) -> 3200.722
A18: Recycled Mat/ Nguyên liệu tái sử dụng (gạch tái sử dụng+bột mài, bột liệu ép, xỉ than tái SD) | B18: ton | C18: =218010/1000+273.92+133.2 -> 625.13 | D18: =156780/1000+117.76+89.6 -> 364.14 | E18: =435240/1000+414.72+255.6 -> 1105.56 | F18: =382200/1000+394.2+275.3 -> 1051.7 | G18: =363480/1000+317.44+308.69 -> 989.61 | H18: =382590/1000+492.57+382.59 -> 1257.75 | I18: =430.7+597.87+399.75 -> 1428.32 | J18: =386880/1000+483.21+403.445 -> 1273.535 | K18: =283920/1000+348.66+284.895 -> 917.475 | L18: =675.09+205.92 -> 881.01 | M18: =305.76+368.55+242.97 -> 917.28 | N18: =340.66+454.83+112.32+114.17 -> 1021.98 | O18: =SUM(C18:N18) -> 11833.49 | P18: =SUM(C18:E18) -> 2094.83 | Q18: =SUM(F18:H18) -> 3299.06 | R18: =SUM(I18:K18) -> 3619.33 | S18: =SUM(L18:N18) -> 2820.27
A19: Others/ Nguyên liệu khác | B19: ton | O19: =SUM(C19:N19) -> 0 | P19: =SUM(C19:E19) -> 0 | Q19: =SUM(F19:H19) -> 0 | R19: =SUM(I19:K19) -> 0 | S19: =SUM(L19:N19) -> 0
A20: Total raw materials/ Tổng nguyên liệu | B20: ton | C20: =SUM(C8:C19) -> 9399.1 | D20: =SUM(D8:D19) -> 7445.692 | E20: =SUM(E8:E19) -> 19799.574 | F20: =SUM(F8:F19) -> 17265.223 | G20: =SUM(G8:G19) -> 16909.903 | H20: =SUM(H8:H19) -> 17831.759 | I20: =SUM(I8:I19) -> 21446.583 | J20: =SUM(J8:J19) -> 18061.408 | ... N20: =SUM(N8:N19) -> 16823.792 | O20: =SUM(C20:N20) -> 185976.07 | P20: =SUM(C20:E20) -> 36644.366 | Q20: =SUM(F20:H20) -> 52006.885 | R20: =SUM(I20:K20) -> 52599.732 | S20: =SUM(L20:N20) -> 44725.087
A21: % Alternative raw materials | B21: % | C21: =C18/C20 -> 0.066509559 | D21: =D18/D20 -> 0.048906133 | E21: =E18/E20 -> 0.055837565 | F21: =F18/F20 -> 0.060914359 | G21: =G18/G20 -> 0.058522512 | H21: =H18/H20 -> 0.070534264 | I21: =I18/I20 -> 0.066598954 | J21: =J18/J20 -> 0.070511391 | ... S21: =S18/S20 -> 0.063057899

Sheet Energy, GHG
A2: Energy Consumption | B2: unit | C2: Jan | D2: Feb | E2: Mar | F2: Apr | G2: May | H2: Jun | I2: Jul | J2: Aug | K2: Sep | L2: Oct | M2: Nov | N2: Dec | O2: YTD | P2: Q1 | Q2: Q2 | R2: Q3 | S2: Q4
A3: Coal/ Than 5A (DV) | B3: Ton | C3: 1233.522 | D3: 983 | E3: =2414661/1000 -> 2414.661 | F3: =2198795/1000 -> 2198.795 | G3: =2197301/1000 -> 2197.301 | H3: =2170990/1000 -> 2170.99 | I3: =2442916/1000 -> 2442.916 | J3: =2148882/1000 -> 2148.882 | K3: =1718913/1000 -> 1718.913 | L3: =1753955/1000 -> 1753.955 | M3: =1649300/1000 -> 1649.3 | N3: =2061215/1000 -> 2061.215 | P3: =SUM(C3:E3) -> 4631.183 | Q3: =SUM(F3:H3) -> 6567.086 | R3: =SUM(I3:K3) -> 6310.711 | S3: =SUM(L3:N3) -> 5464.47
A4: Coal/ Than 4A.1 (DV) | B4: Ton | C4: 443 | D4: =251250/1000 -> 251.25 | E4: =543069/1000 -> 543.069 | F4: =88335/1000 -> 88.335 | G4: =774190/1000 -> 774.19 | H4: =319418/1000 -> 319.418 | I4: =508880/1000 -> 508.88 | J4: =630609/1000 -> 630.609 | K4: =444559/1000 -> 444.559 | L4: =18900/1000 -> 18.9 | M4: =113760/1000 -> 113.76 | N4: =369092/1000 -> 369.092 | P4: =SUM(C4:E4) -> 1237.319 | Q4: =SUM(F4:H4) -> 1181.943 | R4: =SUM(I4:K4) -> 1584.048 | S4: =SUM(L4:N4) -> 501.752
A5: Coal/ Than import coal (DV) (than nhập khẩu) | B5: Ton | C5: 0 | D5: =92480/1000 -> 92.48 | E5: =430117/1000 -> 430.117 | F5: =722734/1000 -> 722.734 | G5: 0 | H5: =434630/1000 -> 434.63 | I5: =375270/1000 -> 375.27 | J5: =77210/1000 -> 77.21 | K5: 0 | L5: =550880/1000 -> 550.88 | M5: =352255/1000 -> 352.255 | N5: =533023/1000 -> 533.023 | P5: =SUM(C5:E5) -> 522.597 | Q5: =SUM(F5:H5) -> 1157.364 | R5: =SUM(I5:K5) -> 452.48 | S5: =SUM(L5:N5) -> 1436.158
A6: Than cám qua sàng / Than 5A under screen DV | B6: Ton | C6: 114 | D6: 88 | E6: =206339/1000 -> 206.339 | F6: =209205/1000 -> 209.205 | G6: =204699/1000 -> 204.699 | H6: =201010/1000 -> 201.01 | I6: =188848/1000 -> 188.848 | J6: =204034/1000 -> 204.034 | K6: =133775/1000 -> 133.775 | L6: =153045/1000 -> 153.045 | M6: =156700/1000 -> 156.7 | N6: =175785/1000 -> 175.785 | P6: =SUM(C6:E6) -> 408.339 | Q6: =SUM(F6:H6) -> 614.914 | R6: =SUM(I6:K6) -> 526.657 | S6: =SUM(L6:N6) -> 485.53
A7: Coal/ Than 5A (YB) | B7: Ton | C7: 0 | D7: 0 | E7: 0 | P7: =SUM(C7:E7) -> 0 | Q7: =SUM(F7:H7) -> 0 | R7: =SUM(I7:K7) -> 0 | S7: =SUM(L7:N7) -> 0
A8: Coal/ Than 4A.1 (YB) | B8: Ton | C8: 0 | D8: 0 | E8: 0 | N8: =27623.11448/1000 -> 27.623114 | P8: =SUM(C8:E8) -> 0 | Q8: =SUM(F8:H8) -> 0 | R8: =SUM(I8:K8) -> 0 | S8: =SUM(L8:N8) -> 27.623114
A9: Coal/ Than import coal (YB) (than nhập khẩu) | B9: Ton | C9: 0 | D9: 0 | E9: 0 | P9: =SUM(C9:E9) -> 0 | Q9: =SUM(F9:H9) -> 0 | R9: =SUM(I9:K9) -> 0 | S9: =SUM(L9:N9) -> 0
A10: Than cám qua sàng / Than 5A under screen YB | B10: Ton | C10: 0 | D10: 0 | E10: 0 | P10: =SUM(C10:L10) -> 0 | Q10: =SUM(F10:H10) -> 0 | R10: =SUM(I10:K10) -> 0 | S10: =SUM(L10:N10) -> 0
A11: Coal/ Than 5A (DV+YB) | B11: Ton | C11: =C3+C7 -> 1233.522 | D11: =D3+D7 -> 983 | E11: =E3+E7 -> 2414.661 | F11: =F3+F7 -> 2198.795 | G11: =G3+G7 -> 2197.301 | H11: =H3+H7 -> 2170.99 | I11: =I3+I7 -> 2442.916 | J11: =J3+J7 -> 2148.882 | ... S11: =S3+S7 -> 5464.47
A12: Coal/ Than 4A.1 (DV+YB) | B12: Ton | C12: =C4+C8 -> 443 | D12: =D4+D8 -> 251.25 | E12: =E4+E8 -> 543.069 | F12: =F4+F8 -> 88.335 | G12: =G4+G8 -> 774.19 | H12: =H4+H8 -> 319.418 | I12: =I4+I8 -> 508.88 | J12: =J4+J8 -> 630.609 | ... S12: =S4+S8 -> 529.37511
A13: Coal/ Than import coal (DV+YB) | B13: Ton | C13: =C5+C9 -> 0 | D13: =D5+D9 -> 92.48 | E13: =E5+E9 -> 430.117 | F13: =F5+F9 -> 722.734 | G13: =G5+G9 -> 0 | H13: =H5+H9 -> 434.63 | I13: =I5+I9 -> 375.27 | J13: =J5+J9 -> 77.21 | ... S13: =S5+S9 -> 1436.158
A14: Coal/ Than 5A under screen (DV+YB) | B14: Ton | C14: =C6+C10 -> 114 | D14: =D6+D10 -> 88 | E14: =E6+E10 -> 206.339 | F14: =F6+F10 -> 209.205 | G14: =G6+G10 -> 204.699 | H14: =H6+H10 -> 201.01 | I14: =I6+I10 -> 188.848 | J14: =J6+J10 -> 204.034 | ... T14: =T6+T10 -> 0
A15: Total Coal DV | B15: Ton | C15: =SUM(C3:C6) -> 1790.522 | D15: =SUM(D3:D6) -> 1414.73 | E15: =SUM(E3:E6) -> 3594.186 | F15: =SUM(F3:F6) -> 3219.069 | G15: =SUM(G3:G6) -> 3176.19 | H15: =SUM(H3:H6) -> 3126.048 | I15: =SUM(I3:I6) -> 3515.914 | J15: =SUM(J3:J6) -> 3060.735 | ... S15: =SUM(S3:S6) -> 7887.91
A16: Total Coal YB | B16: Ton | C16: =SUM(C7:C10) -> 0 | D16: =SUM(D7:D10) -> 0 | E16: =SUM(E7:E10) -> 0 | F16: =SUM(F7:F10) -> 0 | G16: =SUM(G7:G10) -> 0 | H16: =SUM(H7:H10) -> 0 | I16: =SUM(I7:I10) -> 0 | J16: =SUM(J7:J10) -> 0 | ... S16: =SUM(S7:S10) -> 27.623114
A17: Total Coal | B17: Ton | C17: =SUM(C15:C16) -> 1790.522 | D17: =SUM(D15:D16) -> 1414.73 | E17: =SUM(E15:E16) -> 3594.186 | F17: =SUM(F15:F16) -> 3219.069 | G17: =SUM(G15:G16) -> 3176.19 | H17: =SUM(H15:H16) -> 3126.048 | I17: =SUM(I15:I16) -> 3515.914 | J17: =SUM(J15:J16) -> 3060.735 | ... O17: =SUM(O15:O16) -> 0 | P17: =SUM(P11:P13) -> 6391.099 | Q17: =SUM(Q11:Q13) -> 8906.393 | R17: =SUM(R11:R13) -> 8347.239 | S17: =SUM(S11:S13) -> 7430.0031
A18: Coal heating value 5A (Nhiệt trị theo báo cáo gửi ban NL) | B18: cal/g | C18: 7350 | D18: 7350 | E18: 7350 | F18: 7350 | G18: 7350 | H18: 7350 | I18: 7350 | J18: 7350 | K18: 7350 | L18: 7350 | M18: 7350 | N18: 7350 | O18: 7350 | P18: 7350 | Q18: 7350 | R18: 7350 | S18: 7350
A19: Coal heating value 4A.1 (lấy theo nhiệt trị của ban NL) | B19: cal/g | C19: 5780 | D19: 5780 | E19: 5780 | F19: 5780 | G19: 5780 | H19: 5780 | I19: 5780 | J19: 5780 | K19: 5780 | L19: 5780 | M19: 5780 | N19: 5780 | O19: 5780 | P19: 5780 | Q19: 5780 | R19: 5780 | S19: 5780
A20: Coal heating value import coal (Nhiệt trị theo ban NL) | B20: cal/g | C20: 5520 | D20: 5520 | E20: 5520 | F20: 5520 | G20: 5520 | H20: 5520 | I20: 5520 | J20: 5520 | K20: 5520 | L20: 5520 | M20: 5520 | N20: 5520 | O20: 5520 | P20: 5520 | Q20: 5520 | R20: 5520 | S20: 5520
A21: Coal heating value5A under screen (Nhiệt trị theo ban NL) | B21: cal/g | C21: 6810 | D21: 6810 | E21: 6810 | F21: 6810 | G21: 6810 | H21: 6810 | I21: 6810 | J21: 6810 | K21: 6810 | L21: 6810 | M21: 6810 | N21: 6810 | O21: 6810 | P21: 6810 | Q21: 6810 | R21: 6810 | S21: 6810
A22: Coal Heating Value average | B22: cal/g | C22: =((C11*C18)+(C12*C19)+(C13*C20)+(C14*C21))/C17 -> 6927.1792 | D22: =((D11*D18)+(D12*D19)+(D13*D20)+(D14*D21))/D17 -> 6917.9593 | E22: =((E11*E18)+(E12*E19)+(E13*E20)+(E14*E21))/E17 -> 6862.7811 | F22: =((F11*F18)+(F12*F19)+(F13*F20)+(F14*F21))/F17 -> 6860.958 | G22: =((G11*G18)+(G12*G19)+(G13*G20)+(G14*G21))/G17 -> 6932.5137 | H22: =((H11*H18)+(H12*H19)+(H13*H20)+(H14*H21))/H17 -> 6900.4213 | I22: =((I11*I18)+(I12*I19)+(I13*I20)+(I14*I21))/I17 -> 6898.435 | J22: =((J11*J18)+(J12*J19)+(J13*J20)+(J14*J21))/J17 -> 6944.3691 | ... S22: =((S11*S18)+(S12*S19)+(S13*S20)+(S14*S21))/S17 -> 7329.4309
A23: Coal Gas (DV) (Nhiệt trị theo phiếu kiểm tra) | B23: Mcal | C23: 9228477.4 | D23: 4930580 | E23: 18233956 | F23: 16498637 | G23: 15879436 | H23: 16129496 | I23: 18191175 | J23: 16165639 | K23: 12955187 | L23: 12294716 | M23: 12544717 | N23: 15057913 | O23: =SUM(C23:N23) -> 1.6810993e+08 | P23: =SUM(C23:E23) -> 32393014 | Q23: =SUM(F23:H23) -> 48507569 | R23: =SUM(I23:K23) -> 47312001 | S23: =SUM(L23:N23) -> 39897347
A24: Coal Gas (YB) (Nhiệt trị theo phiếu kiểm tra) | B24: Mcal | O24: =SUM(C24:N24) -> 0 | P24: =SUM(C24:E24) -> 0 | Q24: =SUM(F24:H24) -> 0 | R24: =SUM(I24:K24) -> 0 | S24: =SUM(L24:N24) -> 0
A25: Total Coal Gas | B25: Mcal | C25: =SUM(C23:C24) -> 9228477.4 | D25: =SUM(D23:D24) -> 4930580 | E25: =SUM(E23:E24) -> 18233956 | F25: =SUM(F23:F24) -> 16498637 | G25: =SUM(G23:G24) -> 15879436 | H25: =SUM(H23:H24) -> 16129496 | I25: =SUM(I23:I24) -> 18191175 | J25: =SUM(J23:J24) -> 16165639 | ... N25: =SUM(N23:N24) -> 15057913 | O25: =SUM(C25:N25) -> 1.6810993e+08 | P25: =SUM(C25:E25) -> 32393014 | Q25: =SUM(F25:H25) -> 48507569 | R25: =SUM(I25:K25) -> 47312001 | S25: =SUM(L25:N25) -> 39897347
A26: Lignite/ Than non | B26: Ton | O26: =SUM(C26:N26) -> 0 | P26: =SUM(C26:E26) -> 0 | Q26: =SUM(F26:H26) -> 0 | R26: =SUM(I26:K26) -> 0 | S26: =SUM(L26:N26) -> 0
A27: Natural Gas/ Khí gas tự nhiên | B27: Ton | O27: =SUM(C27:N27) -> 0 | P27: =SUM(C27:E27) -> 0 | Q27: =SUM(F27:H27) -> 0 | R27: =SUM(I27:K27) -> 0 | S27: =SUM(L27:N27) -> 0
A28: Co-generation (Heat)/ Đồng phát nhiệt điện | B28: Ton | O28: =SUM(C28:N28) -> 0 | P28: =SUM(C28:E28) -> 0 | Q28: =SUM(F28:H28) -> 0 | R28: =SUM(I28:K28) -> 0 | S28: =SUM(L28:N28) -> 0
A29: LPG for Process used (Station)/ LPG dùng cho trạm (dùng cho lò nung) | B29: Ton | O29: =SUM(C29:N29) -> 0 | P29: =SUM(C29:E29) -> 0 | Q29: =SUM(F29:H29) -> 0 | R29: =SUM(I29:K29) -> 0 | S29: =SUM(L29:N29) -> 0
A30: Heavy fuel oil / Bunker oil/ Dầu nặng hoặc dàu chạy tàu | B30: Ton | O30: =SUM(C30:N30) -> 0 | P30: =SUM(C30:E30) -> 0 | Q30: =SUM(F30:H30) -> 0 | R30: =SUM(I30:K30) -> 0 | S30: =SUM(L30:N30) -> 0
A31: Diesel oil (Mobile) Dầu xe | B31: Litre | C31: 15330 | D31: 17932 | E31: 26113 | F31: 23200 | G31: 27582 | H31: 25780 | I31: 27627 | J31: 27197 | K31: 22566 | L31: 21537 | M31: 26509 | N31: 24880 | O31: =SUM(C31:N31) -> 286253 | P31: =SUM(C31:E31) -> 59375 | Q31: =SUM(F31:H31) -> 76562 | R31: =SUM(I31:K31) -> 77390 | S31: =SUM(L31:N31) -> 72926
A32: Gasoline (xăng bơm chữa cháy) | B32: Litre | C32: 0 | D32: 0 | E32: 0 | F32: 0 | G32: 0 | H32: 0 | I32: 0 | K32: 0 | L32: 0 | M32: 0 | N32: 0 | O32: =SUM(C32:N32) -> 0 | P32: =SUM(C32:E32) -> 0 | Q32: =SUM(F32:H32) -> 0 | R32: =SUM(I32:K32) -> 0 | S32: =SUM(L32:N32) -> 0
A33: Steam/ Hơi nước | B33: Ton | O33: =SUM(C33:N33) -> 0 | P33: =SUM(C33:E33) -> 0 | Q33: =SUM(F33:H33) -> 0 | R33: =SUM(I33:K33) -> 0 | S33: =SUM(L33:N33) -> 0
A34: Solid Biomass (DV) (Củi+rác đốt là cây…+ Gỗ băm) | B34: Ton | C34: 2.446 | D34: =18544/1000 -> 18.544 | E34: =29067/1000 -> 29.067 | F34: =22056/1000+9.88 -> 31.936 | G34: =27452/1000 -> 27.452 | H34: =10810/1000+212.176 -> 222.986 | I34: =9030/1000+336.6 -> 345.63 | J34: =25270/1000+555095/1000 -> 580.365 | K34: =37960/1000+433.165 -> 471.125 | L34: =27.94+280.4 -> 308.34 | M34: =34.666+27.72+77596/1000 -> 139.982 | N34: =15882/1000 -> 15.882 | O34: =SUM(C34:N34) -> 2193.755 | P34: =SUM(C34:E34) -> 50.057 | Q34: =SUM(F34:H34) -> 282.374 | R34: =SUM(I34:K34) -> 1397.12 | S34: =SUM(L34:N34) -> 464.204
A35: Solid Biomass (YB) (Củi+rác đốt) | B35: Ton | C35: 0 | D35: 0 | E35: 0 | F35: 0 | G35: 0 | H35: 0 | I35: 0 | J35: 0 | K35: 0 | L35: 0 | M35: 0 | N35: 0 | O35: =SUM(C35:N35) -> 0 | P35: =SUM(C35:E35) -> 0 | Q35: =SUM(F35:H35) -> 0 | R35: =SUM(I35:K35) -> 0 | S35: =SUM(L35:N35) -> 0
A36: Total Solid Biomass | B36: Ton | C36: =SUM(C34:C35) -> 2.446 | D36: =SUM(D34:D35) -> 18.544 | E36: =SUM(E34:E35) -> 29.067 | F36: =SUM(F34:F35) -> 31.936 | G36: =SUM(G34:G35) -> 27.452 | H36: =SUM(H34:H35) -> 222.986 | I36: =SUM(I34:I35) -> 345.63 | J36: =SUM(J34:J35) -> 580.365 | ... S36: =SUM(S34:S35) -> 464.204
A37: Solid Biomass heating Value (Nhiệt trị) | B37: cal/g | C37: 3000 | D37: 3000 | E37: 3000 | F37: 3000 | G37: 3000 | H37: 3000 | I37: 3000 | J37: 3000 | K37: 3000 | L37: 3000 | M37: 3000 | N37: 3000 | O37: =IF(O36=0,"0",(SUMPRODUCT(C36:N36,C37:N37)/O36)) -> 3000 | P37: =IF(P36=0,"0",(SUMPRODUCT(C36:E36,C37:E37)/P36)) -> 3000 | Q37: =IF(Q36=0,"0",(SUMPRODUCT(F36:H36,F37:H37)/Q36)) -> 3000 | R37: =IF(R36=0,"0",(SUMPRODUCT(I36:K36,I37:K37)/R36)) -> 3000 | S37: =IF(S36=0,"0",(SUMPRODUCT(L36:N36,L37:N37)/S36)) -> 3000
A38: Electricity/ Điện (DV) | B38: MWh | C38: 1214.6904 | D38: =885068.799999999/1000 -> 885.0688 | E38: =2076956.8/1000 -> 2076.9568 | F38: =1968709.6/1000 -> 1968.7096 | G38: =2088979.2/1000 -> 2088.9792 | H38: =2154046.4/1000 -> 2154.0464 | I38: =2334833.6/1000 -> 2334.8336 | J38: =2015340/1000 -> 2015.34 | K38: =1630340.8/1000 -> 1630.3408 | L38: =1631502.4/1000 -> 1631.5024 | M38: =1569298.8/1000 -> 1569.2988 | N38: =1836991.2/1000 -> 1836.9912 | O38: =SUM(C38:N38) -> 21406.758 | P38: =SUM(C38:E38) -> 4176.716 | Q38: =SUM(F38:H38) -> 6211.7352 | R38: =SUM(I38:K38) -> 5980.5144 | S38: =SUM(L38:N38) -> 5037.7924
A39: Electricity/ Điện (YB) | B39: MWh | C39: 0 | D39: 0 | E39: 0 | F39: 0 | G39: 0 | H39: 0 | I39: 0 | J39: 0 | K39: 0 | L39: 0 | M39: 0 | N39: 10.591685 | O39: =SUM(C39:N39) -> 10.591685 | P39: =SUM(C39:E39) -> 0 | Q39: =SUM(F39:H39) -> 0 | R39: =SUM(I39:K39) -> 0 | S39: =SUM(L39:N39) -> 10.591685
A40: Total Electricity | B40: MWh | C40: =SUM(C38:C39) -> 1214.6904 | D40: =SUM(D38:D39) -> 885.0688 | E40: =SUM(E38:E39) -> 2076.9568 | F40: =SUM(F38:F39) -> 1968.7096 | G40: =SUM(G38:G39) -> 2088.9792 | H40: =SUM(H38:H39) -> 2154.0464 | I40: =SUM(I38:I39) -> 2334.8336 | J40: =SUM(J38:J39) -> 2015.34 | ... S40: =SUM(S38:S39) -> 5048.3841
A41: Co-generation (Power)/ Năng lượng đồng phát nhiệt điện | B41: MWh | O41: =SUM(O39:O40) -> 21427.941 | P41: =SUM(P39:P40) -> 4176.716 | Q41: =SUM(Q39:Q40) -> 6211.7352 | R41: =SUM(R39:R40) -> 5980.5144 | S41: =SUM(S39:S40) -> 5058.9758
...

Sheet Energy, GHG (2)
A2: Energy Consumption | B2: unit | C2: Jan | D2: Feb | E2: Mar | F2: Apr | G2: May | H2: Jun | I2: Jul | J2: Aug | K2: Sep | L2: Oct | M2: Nov | N2: Dec | O2: YTD | P2: Q1 | Q2: Q2 | R2: Q3 | S2: Q4
A3: Coal/ Than 5A (DV) | B3: Ton | C3: 1233.522 | D3: 983 | E3: =2414661/1000 -> 2414.661 | F3: =2198795/1000 -> 2198.795 | G3: =2197301/1000 -> 2197.301 | P3: =SUM(C3:E3) -> 4631.183 | Q3: =SUM(F3:H3) -> 4396.096 | R3: =SUM(I3:K3) -> 0 | S3: =SUM(L3:N3) -> 0
A4: Coal/ Than 4A.1 (DV) | B4: Ton | C4: 443 | D4: =251250/1000 -> 251.25 | E4: =543069/1000 -> 543.069 | F4: =88335/1000 -> 88.335 | G4: 574 | P4: =SUM(C4:E4) -> 1237.319 | Q4: =SUM(F4:H4) -> 662.335 | R4: =SUM(I4:K4) -> 0 | S4: =SUM(L4:N4) -> 0
A5: Coal/ Than import coal (DV) (than nhập khẩu) | B5: Ton | C5: 0 | D5: =92480/1000 -> 92.48 | E5: =430117/1000 -> 430.117 | F5: =722734/1000 -> 722.734 | G5: 0 | P5: =SUM(C5:E5) -> 522.597 | Q5: =SUM(F5:H5) -> 722.734 | R5: =SUM(I5:K5) -> 0 | S5: =SUM(L5:N5) -> 0
A6: Than cám qua sàng / Than 5A under screen DV | B6: Ton | C6: 114 | D6: 88 | E6: =206339/1000 -> 206.339 | F6: =209205/1000 -> 209.205 | G6: =204699/1000 -> 204.699 | P6: =SUM(C6:E6) -> 408.339 | Q6: =SUM(F6:H6) -> 413.904 | R6: =SUM(I6:K6) -> 0 | S6: =SUM(L6:N6) -> 0
A7: Coal/ Than 5A (YB) | B7: Ton | C7: 0 | D7: 0 | E7: 0 | P7: =SUM(C7:E7) -> 0 | Q7: =SUM(F7:H7) -> 0 | R7: =SUM(I7:K7) -> 0 | S7: =SUM(L7:N7) -> 0
A8: Coal/ Than 4A.1 (YB) | B8: Ton | C8: 0 | D8: 0 | E8: 0 | P8: =SUM(C8:E8) -> 0 | Q8: =SUM(F8:H8) -> 0 | R8: =SUM(I8:K8) -> 0 | S8: =SUM(L8:N8) -> 0
A9: Coal/ Than import coal (YB) (than nhập khẩu) | B9: Ton | C9: 0 | D9: 0 | E9: 0 | P9: =SUM(C9:E9) -> 0 | Q9: =SUM(F9:H9) -> 0 | R9: =SUM(I9:K9) -> 0 | S9: =SUM(L9:N9) -> 0
A10: Than cám qua sàng / Than 5A under screen YB | B10: Ton | C10: 0 | D10: 0 | E10: 0 | P10: =SUM(C10:L10) -> 0 | Q10: =SUM(F10:H10) -> 0 | R10: =SUM(I10:K10) -> 0 | S10: =SUM(L10:N10) -> 0
A11: Coal/ Than 5A (DV+YB) | B11: Ton | C11: =C3+C7 -> 1233.522 | D11: =D3+D7 -> 983 | E11: =E3+E7 -> 2414.661 | F11: =F3+F7 -> 2198.795 | G11: =G3+G7 -> 2197.301 | H11: =H3+H7 -> 0 | I11: =I3+I7 -> 0 | J11: =J3+J7 -> 0 | ... S11: =S3+S7 -> 0
A12: Coal/ Than 4A.1 (DV+YB) | B12: Ton | C12: =C4+C8 -> 443 | D12: =D4+D8 -> 251.25 | E12: =E4+E8 -> 543.069 | F12: =F4+F8 -> 88.335 | G12: =G4+G8 -> 574 | H12: =H4+H8 -> 0 | I12: =I4+I8 -> 0 | J12: =J4+J8 -> 0 | ... S12: =S4+S8 -> 0
A13: Coal/ Than import coal (DV+YB) | B13: Ton | C13: =C5+C9 -> 0 | D13: =D5+D9 -> 92.48 | E13: =E5+E9 -> 430.117 | F13: =F5+F9 -> 722.734 | G13: =G5+G9 -> 0 | H13: =H5+H9 -> 0 | I13: =I5+I9 -> 0 | J13: =J5+J9 -> 0 | ... S13: =S5+S9 -> 0
A14: Coal/ Than 5A under screen (DV+YB) | B14: Ton | C14: =C6+C10 -> 114 | D14: =D6+D10 -> 88 | E14: =E6+E10 -> 206.339 | F14: =F6+F10 -> 209.205 | G14: =G6+G10 -> 204.699 | H14: =H6+H10 -> 0 | I14: =I6+I10 -> 0 | J14: =J6+J10 -> 0 | ... T14: =T6+T10 -> 0
A15: Total Coal DV | B15: Ton | C15: =SUM(C3:C6) -> 1790.522 | D15: =SUM(D3:D6) -> 1414.73 | E15: =SUM(E3:E6) -> 3594.186 | F15: =SUM(F3:F6) -> 3219.069 | G15: =SUM(G3:G6) -> 2976 | H15: =SUM(H3:H6) -> 0 | I15: =SUM(I3:I6) -> 0 | J15: =SUM(J3:J6) -> 0 | ... S15: =SUM(S3:S6) -> 0
A16: Total Coal YB | B16: Ton | C16: =SUM(C7:C10) -> 0 | D16: =SUM(D7:D10) -> 0 | E16: =SUM(E7:E10) -> 0 | F16: =SUM(F7:F10) -> 0 | G16: =SUM(G7:G10) -> 0 | H16: =SUM(H7:H10) -> 0 | I16: =SUM(I7:I10) -> 0 | J16: =SUM(J7:J10) -> 0 | ... S16: =SUM(S7:S10) -> 0
A17: Total Coal | B17: Ton | C17: =SUM(C15:C16) -> 1790.522 | D17: =SUM(D15:D16) -> 1414.73 | E17: =SUM(E15:E16) -> 3594.186 | F17: =SUM(F15:F16) -> 3219.069 | G17: =SUM(G15:G16) -> 2976 | H17: =SUM(H15:H16) -> 0 | I17: =SUM(I15:I16) -> 0 | J17: =SUM(J15:J16) -> 0 | ... O17: =SUM(O15:O16) -> 0 | P17: =SUM(P11:P13) -> 6391.099 | Q17: =SUM(Q11:Q13) -> 5781.165 | R17: =SUM(R11:R13) -> 0 | S17: =SUM(S11:S13) -> 0
A18: Coal heating value 5A (Nhiệt trị theo báo cáo gửi ban NL) | B18: cal/g | C18: 7350 | D18: 7350 | E18: 7350 | F18: 7350 | G18: 7350 | H18: 7350 | I18: 7350 | J18: 7350 | K18: 7350 | L18: 7350 | M18: 7350 | N18: 7350 | O18: 7350 | P18: 7350 | Q18: 7350 | R18: 7350 | S18: 7350
A19: Coal heating value 4A.1 (lấy theo nhiệt trị của ban NL) | B19: cal/g | C19: 5780 | D19: 5780 | E19: 5780 | F19: 5780 | G19: 5780 | H19: 5780 | I19: 5780 | J19: 5780 | K19: 5780 | L19: 5780 | M19: 5780 | N19: 5780 | O19: 5780 | P19: 5780 | Q19: 5780 | R19: 5780 | S19: 5780
A20: Coal heating value import coal (Nhiệt trị theo ban NL) | B20: cal/g | C20: 5520 | D20: 5520 | E20: 5520 | F20: 5520 | G20: 5520 | H20: 5520 | I20: 5520 | J20: 5520 | K20: 5520 | L20: 5520 | M20: 5520 | N20: 5520 | O20: 5520 | P20: 5520 | Q20: 5520 | R20: 5520 | S20: 5520
A21: Coal heating value5A under screen (Nhiệt trị theo ban NL) | B21: cal/g | C21: 6810 | D21: 6810 | E21: 6810 | F21: 6810 | G21: 6810 | H21: 6810 | I21: 6810 | J21: 6810 | K21: 6810 | L21: 6810 | M21: 6810 | N21: 6810 | O21: 6810 | P21: 6810 | Q21: 6810 | R21: 6810 | S21: 6810
A22: Coal Heating Value average | B22: cal/g | C22: =((C11*C18)+(C12*C19)+(C13*C20)+(C14*C21))/C17 -> 6927.1792 | D22: =((D11*D18)+(D12*D19)+(D13*D20)+(D14*D21))/D17 -> 6917.9593 | E22: =((E11*E18)+(E12*E19)+(E13*E20)+(E14*E21))/E17 -> 6862.7811 | F22: =((F11*F18)+(F12*F19)+(F13*F20)+(F14*F21))/F17 -> 6860.958 | G22: =((G11*G18)+(G12*G19)+(G13*G20)+(G14*G21))/G17 -> 7010.0412 | H22: =((H11*H18)+(H12*H19)+(H13*H20)+(H14*H21))/H17 -> #DIV/0! | I22: =((I11*I18)+(I12*I19)+(I13*I20)+(I14*I21))/I17 -> #DIV/0! | J22: =((J11*J18)+(J12*J19)+(J13*J20)+(J14*J21))/J17 -> #DIV/0! | ... S22: =((S11*S18)+(S12*S19)+(S13*S20)+(S14*S21))/S17 -> #DIV/0!
A23: Coal Gas (DV) (Nhiệt trị theo phiếu kiểm tra) | B23: Mcal | C23: 9228477.4 | D23: 4930580 | E23: 18233956 | F23: 16498637 | G23: 15879436 | O23: =SUM(C23:N23) -> 64771087 | P23: =SUM(C23:E23) -> 32393014 | Q23: =SUM(F23:H23) -> 32378073 | R23: =SUM(I23:K23) -> 0 | S23: =SUM(L23:N23) -> 0
A24: Coal Gas (YB) (Nhiệt trị theo phiếu kiểm tra) | B24: Mcal | O24: =SUM(C24:N24) -> 0 | P24: =SUM(C24:E24) -> 0 | Q24: =SUM(F24:H24) -> 0 | R24: =SUM(I24:K24) -> 0 | S24: =SUM(L24:N24) -> 0
A25: Total Coal Gas | B25: Mcal | C25: =SUM(C23:C24) -> 9228477.4 | D25: =SUM(D23:D24) -> 4930580 | E25: =SUM(E23:E24) -> 18233956 | F25: =SUM(F23:F24) -> 16498637 | G25: =SUM(G23:G24) -> 15879436 | H25: =SUM(H23:H24) -> 0 | I25: =SUM(I23:I24) -> 0 | J25: =SUM(J23:J24) -> 0 | ... N25: =SUM(N23:N24) -> 0 | O25: =SUM(C25:N25) -> 64771087 | P25: =SUM(C25:E25) -> 32393014 | Q25: =SUM(F25:H25) -> 32378073 | R25: =SUM(I25:K25) -> 0 | S25: =SUM(L25:N25) -> 0
A26: Lignite/ Than non | B26: Ton | O26: =SUM(C26:N26) -> 0 | P26: =SUM(C26:E26) -> 0 | Q26: =SUM(F26:H26) -> 0 | R26: =SUM(I26:K26) -> 0 | S26: =SUM(L26:N26) -> 0
A27: Natural Gas/ Khí gas tự nhiên | B27: Ton | O27: =SUM(C27:N27) -> 0 | P27: =SUM(C27:E27) -> 0 | Q27: =SUM(F27:H27) -> 0 | R27: =SUM(I27:K27) -> 0 | S27: =SUM(L27:N27) -> 0
A28: Co-generation (Heat)/ Đồng phát nhiệt điện | B28: Ton | O28: =SUM(C28:N28) -> 0 | P28: =SUM(C28:E28) -> 0 | Q28: =SUM(F28:H28) -> 0 | R28: =SUM(I28:K28) -> 0 | S28: =SUM(L28:N28) -> 0
A29: LPG for Process used (Station)/ LPG dùng cho trạm (dùng cho lò nung) | B29: Ton | O29: =SUM(C29:N29) -> 0 | P29: =SUM(C29:E29) -> 0 | Q29: =SUM(F29:H29) -> 0 | R29: =SUM(I29:K29) -> 0 | S29: =SUM(L29:N29) -> 0
A30: Heavy fuel oil / Bunker oil/ Dầu nặng hoặc dàu chạy tàu | B30: Ton | O30: =SUM(C30:N30) -> 0 | P30: =SUM(C30:E30) -> 0 | Q30: =SUM(F30:H30) -> 0 | R30: =SUM(I30:K30) -> 0 | S30: =SUM(L30:N30) -> 0
A31: Diesel oil (Mobile) Dầu xe | B31: Litre | C31: 15330 | D31: 17932 | E31: 26113 | F31: 23200 | G31: 27582 | O31: =SUM(C31:N31) -> 110157 | P31: =SUM(C31:E31) -> 59375 | Q31: =SUM(F31:H31) -> 50782 | R31: =SUM(I31:K31) -> 0 | S31: =SUM(L31:N31) -> 0
A32: Gasoline (xăng bơm chữa cháy) | B32: Litre | C32: 0 | D32: 0 | E32: 0 | F32: 0 | G32: 0 | H32: 0 | I32: 0 | K32: 0 | L32: 0 | M32: 0 | N32: 0 | O32: =SUM(C32:N32) -> 0 | P32: =SUM(C32:E32) -> 0 | Q32: =SUM(F32:H32) -> 0 | R32: =SUM(I32:K32) -> 0 | S32: =SUM(L32:N32) -> 0
A33: Steam/ Hơi nước | B33: Ton | O33: =SUM(C33:N33) -> 0 | P33: =SUM(C33:E33) -> 0 | Q33: =SUM(F33:H33) -> 0 | R33: =SUM(I33:K33) -> 0 | S33: =SUM(L33:N33) -> 0
A34: Solid Biomass (DV) (Củi+rác đốt là cây...) | B34: Ton | C34: 2.446 | D34: =18544/1000 -> 18.544 | E34: =29067/1000 -> 29.067 | F34: =22056/1000 -> 22.056 | G34: =27452/1000 -> 27.452 | O34: =SUM(C34:N34) -> 99.565 | P34: =SUM(C34:E34) -> 50.057 | Q34: =SUM(F34:H34) -> 49.508 | R34: =SUM(I34:K34) -> 0 | S34: =SUM(L34:N34) -> 0
A35: Solid Biomass (YB) (Củi+rác đốt) | B35: Ton | C35: 0 | D35: 0 | E35: 0 | F35: 0 | G35: 0 | H35: 0 | I35: 0 | J35: 0 | K35: 0 | L35: 0 | M35: 0 | N35: 0 | O35: =SUM(C35:N35) -> 0 | P35: =SUM(C35:E35) -> 0 | Q35: =SUM(F35:H35) -> 0 | R35: =SUM(I35:K35) -> 0 | S35: =SUM(L35:N35) -> 0
A36: Total Solid Biomass | B36: Ton | C36: =SUM(C34:C35) -> 2.446 | D36: =SUM(D34:D35) -> 18.544 | E36: =SUM(E34:E35) -> 29.067 | F36: =SUM(F34:F35) -> 22.056 | G36: =SUM(G34:G35) -> 27.452 | H36: =SUM(H34:H35) -> 0 | I36: =SUM(I34:I35) -> 0 | J36: =SUM(J34:J35) -> 0 | ... S36: =SUM(S34:S35) -> 0
A37: Solid Biomass heating Value (Nhiệt trị) | B37: cal/g | C37: 3000 | D37: 3000 | E37: 3000 | F37: 3000 | G37: 3000 | H37: 3000 | I37: 3000 | J37: 3000 | K37: 3000 | L37: 3000 | M37: 3000 | N37: 3000 | O37: =IF(O36=0,"0",(SUMPRODUCT(C36:N36,C37:N37)/O36)) -> 3000 | P37: =IF(P36=0,"0",(SUMPRODUCT(C36:E36,C37:E37)/P36)) -> 3000 | Q37: =IF(Q36=0,"0",(SUMPRODUCT(F36:H36,F37:H37)/Q36)) -> 3000 | R37: =IF(R36=0,"0",(SUMPRODUCT(I36:K36,I37:K37)/R36)) -> 0 | S37: =IF(S36=0,"0",(SUMPRODUCT(L36:N36,L37:N37)/S36)) -> 0
A38: Electricity/ Điện (DV) | B38: MWh | C38: 1214.6904 | D38: =885068.799999999/1000 -> 885.0688 | E38: =2076956.8/1000 -> 2076.9568 | F38: =1968709.6/1000 -> 1968.7096 | G38: =2088979.2/1000 -> 2088.9792 | O38: =SUM(C38:N38) -> 8234.4048 | P38: =SUM(C38:E38) -> 4176.716 | Q38: =SUM(F38:H38) -> 4057.6888 | R38: =SUM(I38:K38) -> 0 | S38: =SUM(L38:N38) -> 0
A39: Electricity/ Điện (YB) | B39: MWh | C39: 0 | D39: 0 | E39: 0 | F39: 0 | G39: 0 | H39: 0 | I39: 0 | M39: 0 | N39: 0 | O39: =SUM(C39:N39) -> 0 | P39: =SUM(C39:E39) -> 0 | Q39: =SUM(F39:H39) -> 0 | R39: =SUM(I39:K39) -> 0 | S39: =SUM(L39:N39) -> 0
A40: Total Electricity | B40: MWh | C40: =SUM(C38:C39) -> 1214.6904 | D40: =SUM(D38:D39) -> 885.0688 | E40: =SUM(E38:E39) -> 2076.9568 | F40: =SUM(F38:F39) -> 1968.7096 | G40: =SUM(G38:G39) -> 2088.9792 | H40: =SUM(H38:H39) -> 0 | I40: =SUM(I38:I39) -> 0 | J40: =SUM(J38:J39) -> 0 | ... S40: =SUM(S38:S39) -> 0
A41: Co-generation (Power)/ Năng lượng đồng phát nhiệt điện | B41: MWh | O41: =SUM(O39:O40) -> 8234.4048 | P41: =SUM(P39:P40) -> 4176.716 | Q41: =SUM(Q39:Q40) -> 4057.6888 | R41: =SUM(R39:R40) -> 0 | S41: =SUM(S39:S40) -> 0
...

Sheet Water
A2: Water Withdrawal | B2: unit | C2: Jan | D2: Feb | E2: Mar | F2: Apr | G2: May | H2: Jun | I2: Jul | J2: Aug | K2: Sep | L2: Oct | M2: Nov | N2: Dec | O2: YTD | P2: Q1 | Q2: Q2 | R2: Q3 | S2: Q4
A3: Surface water (Lake) (DV) (Nước mặt) | B3: m3 | C3: 4987 | D3: 3058 | E3: 6675 | F3: 6392 | G3: 6393 | H3: 6254 | I3: 6934 | J3: 6241 | K3: 5438 | L3: 6081 | M3: 6741 | N3: 7894 | O3: =SUM(C3:N3) -> 73088 | P3: =SUM(C3:E3) -> 14720 | Q3: =SUM(F3:H3) -> 19039 | R3: =SUM(I3:K3) -> 18613 | S3: =SUM(L3:N3) -> 20716
A4: Surface water (Lake) (YB) (Nước Mặt) | B4: m3 | C4: 0 | D4: 0 | E4: 0 | F4: 0 | G4: 0 | H4: 0 | I4: 0 | J4: 0 | K4: 0 | L4: 0 | M4: 0 | N4: 0 | O4: =SUM(C4:N4) -> 0 | P4: =SUM(C4:E4) -> 0 | Q4: =SUM(F4:H4) -> 0 | R4: =SUM(I4:K4) -> 0 | S4: =SUM(L4:N4) -> 0
A5: Surface water (Lake) (DV+YB) (tổng nước mặt) | B5: m3 | C5: =SUM(C3:C4) -> 4987 | D5: =SUM(D3:D4) -> 3058 | E5: =SUM(E3:E4) -> 6675 | F5: =SUM(F3:F4) -> 6392 | G5: =SUM(G3:G4) -> 6393 | H5: =SUM(H3:H4) -> 6254 | I5: =SUM(I3:I4) -> 6934 | J5: =SUM(J3:J4) -> 6241 | ... S5: =SUM(S3:S4) -> 20716
A6: Ground water (wells) (DV) | B6: m3 | C6: 0 | D6: 0 | E6: 0 | F6: 0 | G6: 0 | H6: 0 | I6: 0 | J6: 0 | O6: =SUM(C6:N6) -> 0 | P6: =SUM(C6:E6) -> 0 | Q6: =SUM(F6:H6) -> 0 | R6: =SUM(I6:K6) -> 0 | S6: =SUM(L6:N6) -> 0
A7: Tap wate (DV) (Nước sạch) | B7: m3 | C7: =1100-442 -> 658 | D7: 1198 | E7: =1525-446 -> 1079 | F7: =1814-522 -> 1292 | G7: =1275-644 -> 631 | H7: =2199-675 -> 1524 | I7: 2083 | J7: =2249-663 -> 1586 | K7: 1369 | L7: 1289 | M7: =2342-616 -> 1726 | N7: 1064 | O7: =SUM(C7:N7) -> 15499 | P7: =SUM(C7:E7) -> 2935 | Q7: =SUM(F7:H7) -> 3447 | R7: =SUM(I7:K7) -> 5038 | S7: =SUM(L7:N7) -> 4079
A8: Total Water Withdrawal (DV) | B8: m3 | C8: =C3+C6+C7 -> 5645 | D8: =D3+D6+D7 -> 4256 | E8: =E3+E6+E7 -> 7754 | F8: =F3+F6+F7 -> 7684 | G8: =G3+G6+G7 -> 7024 | H8: =H3+H6+H7 -> 7778 | I8: =I3+I6+I7 -> 9017 | J8: =J3+J6+J7 -> 7827 | ... S8: =S3+S6+S7 -> 24795
A9: Total Water Withdrawal (YB) | B9: m3 | C9: =C4 -> 0 | D9: =D4 -> 0 | E9: =E4 -> 0 | F9: =F4 -> 0 | G9: =G4 -> 0 | H9: =H4 -> 0 | I9: =I4 -> 0 | J9: =J4 -> 0 | ... L9: =L4 -> 0 | M9: 0 | N9: 0 | O9: =O4 -> 0 | P9: =P4 -> 0 | Q9: =Q4 -> 0 | R9: =R4 -> 0 | S9: =S4 -> 0
A10: Total Water Withdrawal (DV+YB) | B10: m3 | C10: =SUM(C8:C9) -> 5645 | D10: =SUM(D8:D9) -> 4256 | E10: =SUM(E8:E9) -> 7754 | F10: =SUM(F8:F9) -> 7684 | G10: =SUM(G8:G9) -> 7024 | H10: =SUM(H8:H9) -> 7778 | I10: =SUM(I8:I9) -> 9017 | J10: =SUM(J8:J9) -> 7827 | ... S10: =SUM(S8:S9) -> 24795
A11: Specific Water Withdrawal (DV) | B11: m3/ton | C11: =Water!C8/'Production, Raw Mat'!C$3 -> 0.58741317 | D11: =D8/'Production, Raw Mat'!D$3 -> 0.67447629 | E11: =E8/'Production, Raw Mat'!E$3 -> 0.43726451 | F11: =F8/'Production, Raw Mat'!F$3 -> 0.48646904 | G11: =G8/'Production, Raw Mat'!G$3 -> 0.43649561 | H11: =H8/'Production, Raw Mat'!H$3 -> 0.4740366 | I11: =I8/'Production, Raw Mat'!I$3 -> 0.48861178 | J11: =J8/'Production, Raw Mat'!J$3 -> 0.48375642 | K11: =K8/'Production, Raw Mat'!K$3 -> 0.56085807 | ... N11: =N8/'Production, Raw Mat'!N$3 -> 0.57495799 | O11: =O8/[1]Product!O4 -> 885.87 | P11: =P8/[1]Product!P4 -> 176.55 | Q11: =Q8/[1]Product!Q4 -> #DIV/0! | R11: =R8/[1]Product!R4 -> #DIV/0! | S11: =S8/[1]Product!S4 -> #DIV/0!
A12: Specific Water Withdrawal (YB) | B12: m3/ton | C12: =Water!C9/'Production, Raw Mat'!C$4 -> #DIV/0! | D12: =Water!D9/'Production, Raw Mat'!D$4 -> #DIV/0! | E12: =Water!E9/'Production, Raw Mat'!E$4 -> #DIV/0! | F12: =Water!F9/'Production, Raw Mat'!F$4 -> #DIV/0! | G12: =Water!G9/'Production, Raw Mat'!G$4 -> #DIV/0! | H12: =Water!H9/'Production, Raw Mat'!H$4 -> #DIV/0! | I12: =Water!I9/'Production, Raw Mat'!I$4 -> #DIV/0! | J12: =Water!J9/'Production, Raw Mat'!J$4 -> #DIV/0! | ... S12: =Water!S9/'Production, Raw Mat'!S$4 -> 0
A13: Specific Water Withdrawal (DV+YB) | B13: m3/ton | C13: =Water!C10/'Production, Raw Mat'!C$5 -> 0.58741317 | D13: =Water!D10/'Production, Raw Mat'!D$5 -> 0.67447629 | E13: =Water!E10/'Production, Raw Mat'!E$5 -> 0.43726451 | F13: =Water!F10/'Production, Raw Mat'!F$5 -> 0.48646904 | G13: =Water!G10/'Production, Raw Mat'!G$5 -> 0.43649561 | H13: =Water!H10/'Production, Raw Mat'!H$5 -> 0.4740366 | I13: =Water!I10/'Production, Raw Mat'!I$5 -> 0.48861178 | J13: =Water!J10/'Production, Raw Mat'!J$5 -> 0.48375642 | ... S13: =Water!S10/'Production, Raw Mat'!S$5 -> 0.60782602
A15: Water Recycle | B15: unit | C15: Jan | D15: Feb | E15: Mar | F15: Apr | G15: May | H15: Jun | I15: Jul | J15: Aug | K15: Sep | L15: Oct | M15: Nov | N15: Dec | O15: YTD | P15: Q1 | Q15: Q2 | R15: Q3 | S15: Q4
A16: Water Recycle/ Nước tái sử dụng | B16: m3 | C16: =2597+450 -> 3047 | D16: =1561+578 -> 2139 | E16: =5295+374 -> 5669 | F16: 5231 | G16: =4072+381 -> 4453 | H16: =3740+505 -> 4245 | I16: 6172 | J16: 5372 | K16: 4704 | L16: =4212+340 -> 4552 | M16: =4812+375 -> 5187 | N16: =4983+409 -> 5392 | P16: =SUM(C16:E16) -> 10855 | Q16: =SUM(F16:H16) -> 13929 | R16: =SUM(I16:K16) -> 16248 | S16: =SUM(L16:N16) -> 15131
A18: Ko có nước ngầm
A20: Ko có nước ngầm | D20: Jan | E20: Feb | F20: Mar | G20: Apr | H20: May | I20: Jun | J20: Jul | K20: Aug | L20: Sep | M20: Oct | N20: Nov | O20: Dec
C21: Total Water Withdrawal | D21: 12839 | E21: 6903 | F21: 9043 | G21: 11134 | H21: 14106 | I21: 13676 | J21: 13709 | K21: 12091 | L21: 12437 | M21: 10166 | N21: 12485 | O21: 0
C22: Water Recycle/ Nước tái sử dụng | D22: 4254 | E22: 1350 | F22: 4198 | G22: 4986 | H22: 5449 | I22: 4655 | J22: 4177 | K22: 5816 | L22: 5681 | M22: 5544 | N22: 4951

Sheet Waste
A2: Hazardous Waste (ton)/ CHẤT THẢI NGUY HẠI | B2: Jan | G2: Feb | L2: Mar | Q2: Apr | V2: May | AA2: Jun | AF2: Jul | AK2: Aug | AP2: Sep | AU2: Oct | AZ2: Nov | BE2: Dec | BM2: Total (Jan-Dec)
B3: Incoming Stock/ Tồn đầu | C3: Waste generated/ Chất thải phát sinh | D3: Waste Management | G3: Incoming Stock/ Tồn đầu | H3: Waste generated/ Chất thải phát sinh | I3: Waste Management | L3: Incoming Stock/ Tồn đầu | M3: Waste generated/ Chất thải phát sinh | N3: Waste Management | Q3: Incoming Stock/ Tồn đầu | R3: Waste generated/ Chất thải phát sinh | S3: Waste Management | V3: Incoming Stock/ Tồn đầu | W3: Waste generated/ Chất thải phát sinh | X3: Waste Management | AA3: Incoming Stock/ Tồn đầu | AB3: Waste generated/ Chất thải phát sinh | AC3: Waste Management | AF3: Incoming Stock/ Tồn đầu | AG3: Waste generated/ Chất thải phát sinh | AH3: Waste Management | AK3: Incoming Stock/ Tồn đầu | AL3: Waste generated/ Chất thải phát sinh | AM3: Waste Management | AP3: Incoming Stock/ Tồn đầu | AQ3: Waste generated/ Chất thải phát sinh | AR3: Waste Management | AU3: Incoming Stock/ Tồn đầu | AV3: Waste generated/ Chất thải phát sinh | AW3: Waste Management | AZ3: Incoming Stock/ Tồn đầu | BA3: Waste generated/ Chất thải phát sinh | BB3: Waste Management | BE3: Incoming Stock/ Tồn đầu | BF3: Waste generated/ Chất thải phát sinh | BG3: Waste Management | BJ3: Outgoing Stock (Estimate) | BK3: Outgoing Stock (Actual) | BL3: Waste generated (Actual) | BM3: Waste generated | BN3: Landfill
D4: Reuse/Recycle/ Tái sử dụng | E4: Incineration/ Chất thải đốt | F4: Landfill/ CHất thải chôn lấp | I4: Reuse/Recycle/ Tái sử dụng | J4: Incineration/ Chất thải đốt | K4: Landfill/ CHất thải chôn lấp | N4: Reuse/Recycle/ Tái sử dụng | O4: Incineration/ Chất thải đốt | P4: Landfill/ CHất thải chôn lấp | S4: Reuse/Recycle/ Tái sử dụng | T4: Incineration/ Chất thải đốt | U4: Landfill/ CHất thải chôn lấp | X4: Reuse/Recycle/ Tái sử dụng | Y4: Incineration/ Chất thải đốt | Z4: Landfill/ CHất thải chôn lấp | AC4: Reuse/Recycle/ Tái sử dụng | AD4: Incineration/ Chất thải đốt | AE4: Landfill/ CHất thải chôn lấp | AH4: Reuse/Recycle/ Tái sử dụng | AI4: Incineration/ Chất thải đốt | AJ4: Landfill/ CHất thải chôn lấp | AM4: Reuse/Recycle/ Tái sử dụng | AN4: Incineration/ Chất thải đốt | AO4: Landfill/ CHất thải chôn lấp | AR4: Reuse/Recycle/ Tái sử dụng | AS4: Incineration/ Chất thải đốt | AT4: Landfill/ CHất thải chôn lấp | AW4: Reuse/Recycle/ Tái sử dụng | AX4: Incineration/ Chất thải đốt | AY4: Landfill/ CHất thải chôn lấp | BB4: Reuse/Recycle/ Tái sử dụng | BC4: Incineration/ Chất thải đốt | BD4: Landfill/ CHất thải chôn lấp | BG4: Reuse/Recycle/ Tái sử dụng | BH4: Incineration/ Chất thải đốt | BI4: Landfill/ CHất thải chôn lấp
A5: Contaminated Cloth/ Bao gồm giẻ lau, gang tay dính hóa chất, dính dầu | B5: 0.3472 | C5: 0.03 | G5: =(B5+C5)-(D5+E5+F5) -> 0.3772 | H5: 0.4042 | L5: =(G5+H5)-(I5+J5+K5) -> 0.7814 | M5: 0.3202 | Q5: =(L5+M5)-(N5+O5+P5) -> 1.1016 | R5: 0.2031 | V5: =(Q5+R5)-(S5+T5+U5) -> 1.3047 | W5: 0.114 | AA5: =(V5+W5)-(X5+Y5+Z5) -> 1.4187 | AB5: 0.215 | AD5: 0.8 | AF5: =(AA5+AB5)-(AC5+AD5+AE5) -> 0.8337 | AG5: 0.149 | AK5: =(AF5+AG5)-(AH5+AI5+AJ5) -> 0.9827 | AL5: 0.198 | AP5: =(AK5+AL5)-(AM5+AN5+AO5) -> 1.1807 | AQ5: 0.136 | AU5: =(AP5+AQ5)-(AR5+AS5+AT5) -> 1.3167 | AV5: 0.1215 | AZ5: =(AU5+AV5)-(AW5+AX5+AY5) -> 1.4382 | BA5: 0.19 | BE5: =(AZ5+BA5)-(BB5+BC5+BD5) -> 1.6282 | BF5: 0.182 | BJ5: =(BE5+BF5)-(BG5+BH5+BI5) -> 1.8102 | BL5: =(BG5+BH5+BI5)+BK5-BE5 -> -1.6282 | BO5: =C5+H5+M5+R5+W5+AB5+AG5+AL5+AQ5+AV5+BA5+BF5 -> 2.263
A6: Used oil/ Tất cả các loại dầu đã qua sử dụng thải | B6: 5.8526 | C6: 0 | G6: =(B6+C6)-(D6+E6+F6) -> 5.8526 | H6: 6.0424 | J6: 11.095 | L6: =(G6+H6)-(I6+J6+K6) -> 0.8 | M6: 2 | Q6: =(L6+M6)-(N6+O6+P6) -> 2.8 | R6: 0.2 | V6: =(Q6+R6)-(S6+T6+U6) -> 3 | W6: 0 | AA6: =(V6+W6)-(X6+Y6+Z6) -> 3 | AB6: 1 | AF6: =(AA6+AB6)-(AC6+AD6+AE6) -> 4 | AG6: 0 | AK6: =(AF6+AG6)-(AH6+AI6+AJ6) -> 4 | AL6: 0.2 | AN6: 3.062 | AP6: =(AK6+AL6)-(AM6+AN6+AO6) -> 1.138 | AQ6: 0 | AU6: =(AP6+AQ6)-(AR6+AS6+AT6) -> 1.138 | AV6: 0.2 | AZ6: =(AU6+AV6)-(AW6+AX6+AY6) -> 1.338 | BA6: 0 | BE6: =(AZ6+BA6)-(BB6+BC6+BD6) -> 1.338 | BF6: 1.7 | BJ6: =(BE6+BF6)-(BG6+BH6+BI6) -> 3.038 | BL6: =(BG6+BH6+BI6)+BK6-BE6 -> -1.338 | BO6: =BO5-BJ5 -> 0.4528
A7: Package contaminated / Vỏ thùng sơn, vỏ thùng dính dầu thải, các loại bao bì nhựa hoặc kim loại dính hóa chất, | B7: 2.413 | C7: 0.1281 | G7: =(B7+C7)-(D7+E7+F7) -> 2.5411 | H7: 0.1866 | I7: 0.805 | L7: =(G7+H7)-(I7+J7+K7) -> 1.9227 | M7: 0.2339 | Q7: =(L7+M7)-(N7+O7+P7) -> 2.1566 | R7: 0.1807 | V7: =(Q7+R7)-(S7+T7+U7) -> 2.3373 | W7: 0.201 | AA7: =(V7+W7)-(X7+Y7+Z7) -> 2.5383 | AB7: 0.333 | AC7: 0.96 | AF7: =(AA7+AB7)-(AC7+AD7+AE7) -> 1.9113 | AG7: 0.1405 | AK7: =(AF7+AG7)-(AH7+AI7+AJ7) -> 2.0518 | AL7: 0.934 | AM7: =0.6825+1.1125 -> 1.795 | AP7: =(AK7+AL7)-(AM7+AN7+AO7) -> 1.1908 | AQ7: 0.1742 | AU7: =(AP7+AQ7)-(AR7+AS7+AT7) -> 1.365 | AV7: 0.2145 | AZ7: =(AU7+AV7)-(AW7+AX7+AY7) -> 1.5795 | BA7: 0.2105 | BE7: =(AZ7+BA7)-(BB7+BC7+BD7) -> 1.79 | BF7: 0.185 | BJ7: =(BE7+BF7)-(BG7+BH7+BI7) -> 1.975 | BL7: =(BG7+BH7+BI7)+BK7-BE7 -> -1.79
A8: Electronic equipment / Các thiết bị điện thải bao gồm các thiết bị điện, các loại bóng đèn thải, ắc quy, pin hỏng | B8: 0.1484 | C8: 0.013 | G8: =(B8+C8)-(D8+E8+F8) -> 0.1614 | H8: 0.022 | L8: =(G8+H8)-(I8+J8+K8) -> 0.1834 | M8: 0.0096 | Q8: =(L8+M8)-(N8+O8+P8) -> 0.193 | R8: 0.005 | V8: =(Q8+R8)-(S8+T8+U8) -> 0.198 | W8: 0 | AA8: =(V8+W8)-(X8+Y8+Z8) -> 0.198 | AB8: 0.01 | AF8: =(AA8+AB8)-(AC8+AD8+AE8) -> 0.208 | AG8: 0.007 | AK8: =(AF8+AG8)-(AH8+AI8+AJ8) -> 0.215 | AL8: 0.0183 | AN8: =76/1000 -> 0.076 | AP8: =(AK8+AL8)-(AM8+AN8+AO8) -> 0.1573 | AQ8: 0.015 | AU8: =(AP8+AQ8)-(AR8+AS8+AT8) -> 0.1723 | AV8: 0.008 | AZ8: =(AU8+AV8)-(AW8+AX8+AY8) -> 0.1803 | BA8: 0.003 | BE8: =(AZ8+BA8)-(BB8+BC8+BD8) -> 0.1833 | BF8: 0.005 | BJ8: =(BE8+BF8)-(BG8+BH8+BI8) -> 0.1883 | BL8: =(BG8+BH8+BI8)+BK8-BE8 -> -0.1833
A9: Insulation/ Vật liệu cách nhiệt (amiăng thải, bông thủy tinh) | B9: 1.6998 | C9: 0.029 | G9: =(B9+C9)-(D9+E9+F9) -> 1.7288 | H9: =0.2406+0.0636 -> 0.3042 | L9: =(G9+H9)-(I9+J9+K9) -> 2.033 | M9: 0.078 | Q9: =(L9+M9)-(N9+O9+P9) -> 2.111 | R9: 0.1418 | V9: =(Q9+R9)-(S9+T9+U9) -> 2.2528 | W9: 0.231 | AA9: =(V9+W9)-(X9+Y9+Z9) -> 2.4838 | AB9: =0.0425+0.017 -> 0.0595 | AF9: =(AA9+AB9)-(AC9+AD9+AE9) -> 2.5433 | AG9: 0.004 | AK9: =(AF9+AG9)-(AH9+AI9+AJ9) -> 2.5473 | AL9: 0.007 | AP9: =(AK9+AL9)-(AM9+AN9+AO9) -> 2.5543 | AQ9: 0.108 | AU9: =(AP9+AQ9)-(AR9+AS9+AT9) -> 2.6623 | AV9: 5.015 | AX9: 6.46 | AZ9: =(AU9+AV9)-(AW9+AX9+AY9) -> 1.2173 | BA9: 0.005 | BE9: =(AZ9+BA9)-(BB9+BC9+BD9) -> 1.2223 | BF9: 0.03 | BJ9: =(BE9+BF9)-(BG9+BH9+BI9) -> 1.2523 | BL9: =(BG9+BH9+BI9)+BK9-BE9 -> -1.2223
A10: Đất dính hóa chất | B10: 0.2316 | C10: 0 | G10: =(B10+C10)-(D10+E10+F10) -> 0.2316 | H10: 0 | L10: =(G10+H10)-(I10+J10+K10) -> 0.2316 | M10: 0 | Q10: =(L10+M10)-(N10+O10+P10) -> 0.2316 | R10: 0 | V10: =(Q10+R10)-(S10+T10+U10) -> 0.2316 | W10: 0 | AA10: =(V10+W10)-(X10+Y10+Z10) -> 0.2316 | AB10: 0 | AF10: =(AA10+AB10)-(AC10+AD10+AE10) -> 0.2316 | AG10: 0 | AK10: =(AF10+AG10)-(AH10+AI10+AJ10) -> 0.2316 | AL10: 0 | AP10: =(AK10+AL10)-(AM10+AN10+AO10) -> 0.2316 | AQ10: 0 | AU10: =(AP10+AQ10)-(AR10+AS10+AT10) -> 0.2316 | AV10: 0 | AZ10: =(AU10+AV10)-(AW10+AX10+AY10) -> 0.2316 | BA10: 0 | BE10: =(AZ10+BA10)-(BB10+BC10+BD10) -> 0.2316 | BF10: 0 | BJ10: =(BE10+BF10)-(BG10+BH10+BI10) -> 0.2316 | BL10: =(BG10+BH10+BI10)+BK10-BE10 -> -0.2316
A11: Cặn rắn từ quá trình sử lý men | B11: 0.04 | C11: 0 | G11: =(B11+C11)-(D11+E11+F11) -> 0.04 | H11: 0 | L11: =(G11+H11)-(I11+J11+K11) -> 0.04 | M11: 0 | Q11: =(L11+M11)-(N11+O11+P11) -> 0.04 | R11: 0 | V11: =(Q11+R11)-(S11+T11+U11) -> 0.04 | W11: 0 | AA11: =(V11+W11)-(X11+Y11+Z11) -> 0.04 | AB11: 0 | AF11: =(AA11+AB11)-(AC11+AD11+AE11) -> 0.04 | AG11: 0 | AK11: =(AF11+AG11)-(AH11+AI11+AJ11) -> 0.04 | AL11: 0 | AP11: =(AK11+AL11)-(AM11+AN11+AO11) -> 0.04 | AQ11: 0 | AU11: =(AP11+AQ11)-(AR11+AS11+AT11) -> 0.04 | AV11: 0 | AZ11: =(AU11+AV11)-(AW11+AX11+AY11) -> 0.04 | BA11: 0 | BE11: =(AZ11+BA11)-(BB11+BC11+BD11) -> 0.04 | BF11: 0 | BJ11: =(BE11+BF11)-(BG11+BH11+BI11) -> 0.04 | BL11: =(BG11+BH11+BI11)+BK11-BE11 -> -0.04
A12: Nước rửa băng tải | C12: 0 | H12: 0 | M12: 0 | W12: 0 | AB12: 0
B13: 0 | G13: =(B13+C13)-(D13+E13+F13) -> 0 | H13: 0 | L13: =(G13+H13)-(I13+J13+K13) -> 0 | Q13: =(L13+M13)-(N13+O13+P13) -> 0 | V13: =(Q13+R13)-(S13+T13+U13) -> 0 | AA13: =(V13+W13)-(X13+Y13+Z13) -> 0 | AF13: =(AA13+AB13)-(AC13+AD13+AE13) -> 0 | AK13: =(AF13+AG13)-(AH13+AI13+AJ13) -> 0 | AP13: =(AK13+AL13)-(AM13+AN13+AO13) -> 0 | AU13: =(AP13+AQ13)-(AR13+AS13+AT13) -> 0 | AZ13: =(AU13+AV13)-(AW13+AX13+AY13) -> 0 | BE13: =(AZ13+BA13)-(BB13+BC13+BD13) -> 0 | BJ13: =(BE13+BF13)-(BG13+BH13+BI13) -> 0 | BL13: =(BG13+BH13+BI13)+BK13-BE13 -> 0
A14: Total Hazardous Waste Generate (ton) | B14: =SUM(B5:B13) -> 10.7326 | C14: =SUM(C5:C13) -> 0.2001 | D14: =SUM(D5:D13) -> 0 | E14: =SUM(E5:E13) -> 0 | F14: =SUM(F5:F13) -> 0 | G14: =SUM(G5:G13) -> 10.9327 | H14: =SUM(H5:H13) -> 6.9594 | I14: =SUM(I5:I13) -> 0.805 | ... BL14: =SUM(BL5:BL13) -> -6.4334 | BM14: =C14+H14+M14+R14+W14+AB14+AG14+AL14+AQ14+AV14+BA14+BF14 -> 22.8558 | BN14: =F14+K14+P14+U14+Z14+AE14+AJ14+AO14+AT14+AY14+BD14+BI14 -> 0
A15: Specific Hazardous Waste Generate (kg/ton) | C15: =C14*1000/'Production, Raw Mat'!C$5 -> 0.02082221 | F15: =F14*1000/'Production, Raw Mat'!C$3 -> 0 | H15: =H14*1000/'Production, Raw Mat'!D$5 -> 1.1029019 | K15: =K14*1000/'Production, Raw Mat'!D$5 -> 0 | M15: =M14*1000/'Production, Raw Mat'!E$5 -> 0.14897107 | P15: =P14*1000/'Production, Raw Mat'!E$5 -> 0 | R15: =R14*1000/'Production, Raw Mat'!F$5 -> 0.046253811 | U15: =U14*1000/'Production, Raw Mat'!F$5 -> 0 | W15: =W14*1000/'Production, Raw Mat'!G$5 -> 0.033930325 | Z15: =Z14*1000/'Production, Raw Mat'!G$5 -> 0 | AB15: =AB14*1000/'Production, Raw Mat'!H$5 -> 0.098579866 | AE15: =AE14*1000/'Production, Raw Mat'!H$5 -> 0 | AG15: =AG14*1000/'Production, Raw Mat'!I$5 -> 0.016283447 | AJ15: =AJ14*1000/'Production, Raw Mat'!I$5 -> 0 | AL15: =AL14*1000/'Production, Raw Mat'!J$5 -> 0.083889433 | AO15: =AO14*1000/'Production, Raw Mat'!J$5 -> 0 | AQ15: =AQ14*1000/'Production, Raw Mat'!K$5 -> 0.035693215 | AT15: =AT14*1000/'Production, Raw Mat'!K$5 -> 0 | AV15: =AV14*1000/'Production, Raw Mat'!L$5 -> 0.44597439 | AY15: =AY14*1000/'Production, Raw Mat'!L$5 -> 0 | BA15: =BA14*1000/'Production, Raw Mat'!M$5 -> 0.033146314 | BD15: =BD14*1000/'Production, Raw Mat'!M$5 -> 0 | BF15: =BF14*1000/'Production, Raw Mat'!R$5 -> 0.044942653 | BI15: =BI14*1000/'Production, Raw Mat'!N$5 -> 0 | BL15: =BL14*1000/'Production, Raw Mat'!N$5 -> -0.40198861 | BM15: =BM14*1000/'Production, Raw Mat'!$O$5 -> 0.13483302 | BN15: =BN14*1000/'Production, Raw Mat'!$O$5 -> 0
A17: Non Hazardous Waste (ton)/ CHẤT THẢI THÔNG THƯỜNG | B17: Jan | G17: Feb | L17: Mar | Q17: Apr | V17: May | AA17: Jun | AF17: Jul | AK17: Aug | AP17: Sep | AU17: Oct | AZ17: Nov | BE17: Dec | BM17: Total (Jan-Dec)
B18: Incoming Stock/ Tồn đầu | C18: Waste generated/ Chất thải phát sinh | D18: Waste Management | G18: Incoming Stock/ Tồn đầu | H18: Waste generated/ Chất thải phát sinh | I18: Waste Management | L18: Incoming Stock/ Tồn đầu | M18: Waste generated/ Chất thải phát sinh | N18: Waste Management | Q18: Incoming Stock/ Tồn đầu | R18: Waste generated/ Chất thải phát sinh | S18: Waste Management | V18: Incoming Stock/ Tồn đầu | W18: Waste generated/ Chất thải phát sinh | X18: Waste Management | AA18: Incoming Stock/ Tồn đầu | AB18: Waste generated/ Chất thải phát sinh | AC18: Waste Management | AF18: Incoming Stock/ Tồn đầu | AG18: Waste generated/ Chất thải phát sinh | AH18: Waste Management | AK18: Incoming Stock/ Tồn đầu | AL18: Waste generated/ Chất thải phát sinh | AM18: Waste Management | AP18: Incoming Stock/ Tồn đầu | AQ18: Waste generated/ Chất thải phát sinh | AR18: Waste Management | AU18: Incoming Stock/ Tồn đầu | AV18: Waste generated/ Chất thải phát sinh | AW18: Waste Management | AZ18: Incoming Stock/ Tồn đầu | BA18: Waste generated/ Chất thải phát sinh | BB18: Waste Management | BE18: Incoming Stock/ Tồn đầu | BF18: Waste generated/ Chất thải phát sinh | BG18: Waste Management | BJ18: Outgoing Stock (Estimate) | BK18: Outgoing Stock (Actual) | BL18: Waste generated (Actual) | BM18: Waste generated | BN18: Landfill
D19: Reuse/Recycle/ Tái sử dụng | E19: Incineration/ Chất thải đốt | F19: Landfill/ CHất thải chôn lấp | I19: Reuse/Recycle/ Tái sử dụng | J19: Incineration/ Chất thải đốt | K19: Landfill/ CHất thải chôn lấp | N19: Reuse/Recycle/ Tái sử dụng | O19: Incineration/ Chất thải đốt | P19: Landfill/ CHất thải chôn lấp | S19: Reuse/Recycle/ Tái sử dụng | T19: Incineration/ Chất thải đốt | U19: Landfill/ CHất thải chôn lấp | X19: Reuse/Recycle/ Tái sử dụng | Y19: Incineration/ Chất thải đốt | Z19: Landfill/ CHất thải chôn lấp | AC19: Reuse/Recycle/ Tái sử dụng | AD19: Incineration/ Chất thải đốt | AE19: Landfill/ CHất thải chôn lấp | AH19: Reuse/Recycle/ Tái sử dụng | AI19: Incineration/ Chất thải đốt | AJ19: Landfill/ CHất thải chôn lấp | AM19: Reuse/Recycle/ Tái sử dụng | AN19: Incineration/ Chất thải đốt | AO19: Landfill/ CHất thải chôn lấp | AR19: Reuse/Recycle/ Tái sử dụng | AS19: Incineration/ Chất thải đốt | AT19: Landfill/ CHất thải chôn lấp | AW19: Reuse/Recycle/ Tái sử dụng | AX19: Incineration/ Chất thải đốt | AY19: Landfill/ CHất thải chôn lấp | BB19: Reuse/Recycle/ Tái sử dụng | BC19: Incineration/ Chất thải đốt | BD19: Landfill/ CHất thải chôn lấp | BG19: Reuse/Recycle/ Tái sử dụng | BH19: Incineration/ Chất thải đốt | BI19: Landfill/ CHất thải chôn lấp
A20: Tiles after kiln, coal slag/ Gạch sau nung, sỉ than, | B20: 0 | C20: =68780/1000 -> 68.78 | D20: =68780/1000 -> 68.78 | G20: =(B20+C20)-(D20+E20+F20) -> 0 | H20: =195200/1000 -> 195.2 | J20: 195.2 | L20: =(G20+H20)-(I20+J20+K20) -> 0 | M20: 0 | Q20: =(L20+M20)-(N20+O20+P20) -> 0 | R20: 0 | V20: =(Q20+R20)-(S20+T20+U20) -> 0 | W20: 0 | AA20: =(V20+W20)-(X20+Y20+Z20) -> 0 | AB20: 0 | AF20: =(AA20+AB20)-(AC20+AD20+AE20) -> 0 | AG20: 0 | AK20: =(AF20+AG20)-(AH20+AI20+AJ20) -> 0 | AL20: 0 | AP20: =(AK20+AL20)-(AM20+AN20+AO20) -> 0 | AQ20: 0 | AU20: =(AP20+AQ20)-(AR20+AS20+AT20) -> 0 | AV20: 0 | AZ20: =(AU20+AV20)-(AW20+AX20+AY20) -> 0 | BA20: 0 | BE20: =(AZ20+BA20)-(BB20+BC20+BD20) -> 0 | BF20: 0 | BJ20: =(BE20+BF20)-(BG20+BH20+BI20) -> 0 | BL20: =(BG20+BH20+BI20)+BK20-BE20 -> 0
A21: Sludge/ Bùn | B21: 0 | C21: 0 | G21: =(B21+C21)-(D21+E21+F21) -> 0 | H21: 0 | L21: =(G21+H21)-(I21+J21+K21) -> 0 | M21: 0 | Q21: =(L21+M21)-(N21+O21+P21) -> 0 | R21: 0 | V21: =(Q21+R21)-(S21+T21+U21) -> 0 | W21: 0 | AA21: =(V21+W21)-(X21+Y21+Z21) -> 0 | AB21: 0 | AF21: =(AA21+AB21)-(AC21+AD21+AE21) -> 0 | AG21: 0 | AK21: =(AF21+AG21)-(AH21+AI21+AJ21) -> 0 | AL21: 0 | AP21: =(AK21+AL21)-(AM21+AN21+AO21) -> 0 | AQ21: 0 | AU21: =(AP21+AQ21)-(AR21+AS21+AT21) -> 0 | AV21: 0 | AZ21: =(AU21+AV21)-(AW21+AX21+AY21) -> 0 | BA21: 0 | BE21: =(AZ21+BA21)-(BB21+BC21+BD21) -> 0 | BF21: 0 | BJ21: =(BE21+BF21)-(BG21+BH21+BI21) -> 0 | BL21: =(BG21+BH21+BI21)+BK21-BE21 -> 0
A22: Paper packaging/ Giấy bao bì, các loại giấy bỏ, cốt băng dính, bao bì catton, hộp catton | B22: 0 | C22: 1.92 | D22: 1.92 | G22: =(B22+C22)-(D22+E22+F22) -> 0 | H22: 0 | L22: =(G22+H22)-(I22+J22+K22) -> 0 | M22: 1.4 | N22: 1.4 | Q22: =(L22+M22)-(N22+O22+P22) -> 0 | R22: 0 | V22: =(Q22+R22)-(S22+T22+U22) -> 0 | W22: 4.82 | X22: 4.82 | AA22: =(V22+W22)-(X22+Y22+Z22) -> 0 | AB22: 0 | AF22: =(AA22+AB22)-(AC22+AD22+AE22) -> 0 | AG22: 1.52 | AH22: 1.52 | AK22: =(AF22+AG22)-(AH22+AI22+AJ22) -> 0 | AL22: 0 | AP22: =(AK22+AL22)-(AM22+AN22+AO22) -> 0 | AQ22: 1.68 | AR22: 1.68 | AU22: =(AP22+AQ22)-(AR22+AS22+AT22) -> 0 | AV22: 0 | AZ22: =(AU22+AV22)-(AW22+AX22+AY22) -> 0 | BA22: 1.58 | BB22: 1.58 | BE22: =(AZ22+BA22)-(BB22+BC22+BD22) -> 0 | BF22: 1.42 | BG22: 1.42 | BJ22: =(BE22+BF22)-(BG22+BH22+BI22) -> 0 | BL22: =(BG22+BH22+BI22)+BK22-BE22 -> 1.42
A23: Plastic packaging, (Wrap, Bigbag)/ Nhựa bao gồm các loại vật dụng làm từ nhựa bỏ | B23: 0 | C23: 0.58 | D23: 0.58 | G23: =(B23+C23)-(D23+E23+F23) -> 0 | H23: 0 | L23: =(G23+H23)-(I23+J23+K23) -> 0 | M23: 0.26 | N23: 0.26 | Q23: =(L23+M23)-(N23+O23+P23) -> 0 | R23: 0 | V23: =(Q23+R23)-(S23+T23+U23) -> 0 | W23: 0.42 | X23: 0.42 | AA23: =(V23+W23)-(X23+Y23+Z23) -> 0 | AB23: 0 | AF23: =(AA23+AB23)-(AC23+AD23+AE23) -> 0 | AG23: 0.38 | AH23: 0.38 | AK23: =(AF23+AG23)-(AH23+AI23+AJ23) -> 0 | AL23: 0.177 | AM23: 0.177 | AP23: =(AK23+AL23)-(AM23+AN23+AO23) -> 0 | AQ23: 0.38 | AR23: 0.38 | AU23: =(AP23+AQ23)-(AR23+AS23+AT23) -> 0 | AV23: 0 | AZ23: =(AU23+AV23)-(AW23+AX23+AY23) -> 0 | BA23: 0.22 | BB23: 0.22 | BE23: =(AZ23+BA23)-(BB23+BC23+BD23) -> 0 | BF23: 0.24 | BG23: 0.24 | BJ23: =(BE23+BF23)-(BG23+BH23+BI23) -> 0 | BL23: =(BG23+BH23+BI23)+BK23-BE23 -> 0.24
A24: Wooden Packaging (Pallet, gỗ củi) | B24: 0 | C24: 0 | G24: =(B24+C24)-(D24+E24+F24) -> 0 | H24: 0 | L24: =(G24+H24)-(I24+J24+K24) -> 0 | M24: 0 | Q24: =(L24+M24)-(N24+O24+P24) -> 0 | R24: 0 | V24: =(Q24+R24)-(S24+T24+U24) -> 0 | W24: 0 | AA24: =(V24+W24)-(X24+Y24+Z24) -> 0 | AB24: 0 | AF24: =(AA24+AB24)-(AC24+AD24+AE24) -> 0 | AG24: 0 | AK24: =(AF24+AG24)-(AH24+AI24+AJ24) -> 0 | AL24: 0 | AP24: =(AK24+AL24)-(AM24+AN24+AO24) -> 0 | AQ24: 0 | AU24: =(AP24+AQ24)-(AR24+AS24+AT24) -> 0 | AV24: 0 | AZ24: =(AU24+AV24)-(AW24+AX24+AY24) -> 0 | BA24: 0 | BE24: =(AZ24+BA24)-(BB24+BC24+BD24) -> 0 | BF24: 0 | BJ24: =(BE24+BF24)-(BG24+BH24+BI24) -> 0 | BL24: =(BG24+BH24+BI24)+BK24-BE24 -> 0
